Workbook

Sheet Hoja1
B1: Rubro | C1: Artículos | D1: Proveedor | E1: Habitual | G1: Moneda | H1: Unidad
B2: Embalaje | C2: Lunares 30mm (Blanco) | D2: Mix-57 | E2: si | G2: ARS | H2: kg
B3: Embalaje | C3: Lunares 30mm (Negro) | D3: Mix-57 | E3: si | G3: USD | H3: unidad
B4: Embalaje | C4: Lunares 30mm (Azul) | D4: Mix-57 | E4: si | H4: par
B5: Embalaje | C5: Lunares 30mm (Naranja) | D5: Mix-57 | E5: si | H5: bolsa
B6: Embalaje | C6: Lunares 15mm (Blanco) | D6: Mix-57 | E6: si | H6: rollo
B7: Embalaje | C7: Lunares 15mm (Negro) | D7: Mix-57 | E7: si | H7: m3
B8: Embalaje | C8: Lunares 15mm (Azul) | D8: Mix-57 | E8: si | H8: litro
B9: Embalaje | C9: Etiquetas DK 2205 (Fleje) | D9: Mix-57 | E9: si | H9: m
B10: Embalaje | C10: Etiquetas DK 1226 (Estandar) | D10: Mix-57 | E10: si | H10: bidón
B11: Embalaje | C11: Etiquetas Dobles 50x29 (embalaje) | D11: Mix-57 | E11: si
B12: Embalaje | C12: Etiquetas 30mm cuadrado (Verde) | D12: Mix-57 | E12: si
B13: Pintura | C13: Pinceles | D13: Coiro | E13: si
B14: Soldadura | C14: Tobera MB25 (Herrería) | D14: Diprov | E14: si
B15: Soldadura | C15: Difusor de Gas (Herrería) | D15: Diprov | E15: si
B16: Soldadura | C16: Repuesto roscado caudalímetro (Herrería) | D16: Diprov | E16: si
B17: Soldadura | C17: TUBO M6 0.9mm (Herrería) | D17: Diprov | E17: si
B18: Soldadura | C18: Lente máscara de soldar | D18: Diprov | E18: si
B19: Farmacia | C19: Curitas | D19: Farmacia | E19: si
B20: Farmacia | C20: Jabón neutro | D20: Farmacia | E20: si
B21: Farmacia | C21: Agua oxigenada | D21: Farmacia | E21: si
B22: Farmacia | C22: Alcohol | D22: Farmacia | E22: si
... B37: Lubricantes | C37: Lubricantes Aerosol | D37: Fercol | E37: si
B38: Lubricantes | C38: Limpia contactos
B39: Lubricantes | C39: Aceite DRAFOS MNL (Base SMR)
B40: Soldadura | C40: Pasta Antiadherente (Herrería) | D40: Diprov | E40: si
B41: Pintura | C41: Aerosol Negro Semi-mate | D41: Pinturería Giannoni | E41: si
B42: Pintura | C42: Aeroso Blanco Semi-mate | D42: Pinturería Giannoni | E42: si
B43: Herramientas | C43: Disco Sensitiva 350 mm | D43: Wurth | E43: si
B44: Herramientas | C44: Tijera corta chapa | D44: Coiro | E44: si
B45: Herramientas | C45: Hoja de Sierra P/Serrucho L2450mm | D45: Alpamet | E45: si
B46: Lubricantes | C46: Agua Destilada
B47: EPP | C47: Anteojos Seguridad | D47: Tech Safe | E47: si
B48: EPP | C48: Faja Lumbar TALLE S | D48: Tech Safe | E48: si
B49: EPP | C49: Faja Lumbar TALLE M | D49: Tech Safe | E49: si
B50: EPP | C50: Faja Lumbar TALLE L | D50: Tech Safe | E50: si
B51: EPP | C51: Faja Lumbar TALLE XL | D51: Tech Safe | E51: si
B52: EPP | C52: Faja Lumbar TALLE XXL | D52: Tech Safe | E52: si
B53: EPP | C53: Guantes Dyne 5 | D53: Roguant | E53: si
B54: EPP | C54: Guantes Poli (Tactil) 8# | D54: Roguant | E54: si
...

Sheet Historial de compras
A1: Fecha | B1: Mes | C1: Artículo | D1: Rubro | E1: Proveedor | F1: Cantidad | G1: Unidad | H1: Precio Unitario ARS | I1: Precio Unitario USD | J1: DTO | K1: Moneda | L1: IVA | M1: Subtotal ARS | N1: TOTAL ARS | O1: TOTAL USD | P1: TC BNA | Q1: Observaciones
A2: 46154 | B2: =MONTH(Tabla2[[#This Row],[Fecha]]) -> 5 | C2: Stretch 10 cm | D2: =IFERROR(_xlfn.XLOOKUP(Tabla2[[#This Row],[Artículo]],Tabla1[Artículos],Tabla1[Rubro]),"") -> Embalaje | E2: Mad Packaging | F2: 185 | G2: kg | H2: 4528 | I2: =Tabla2[[#This Row],[Precio Unitario ARS]]/Tabla2[[#This Row],[TC BNA]] -> 3.2227758 | J2: 0 | K2: ARS | L2: 0.21 | M2: =(Tabla2[[#This Row],[Precio Unitario ARS]]-(Tabla2[[#This Row],[Precio Unitario ARS]]*Tabla2[[#This Row],[DTO]]))*Tabla2[[#This Row],[Cantidad]] -> 837680 | N2: =Tabla2[[#This Row],[Subtotal ARS]]+(Tabla2[[#This Row],[Subtotal ARS]]*Tabla2[[#This Row],[IVA]]) -> 1013592.8 | O2: =Tabla2[[#This Row],[TOTAL ARS]]/Tabla2[[#This Row],[TC BNA]] -> 721.41836 | P2: =_xlfn.XLOOKUP(A2,'TC_BNA xlsx'!A:A,'TC_BNA xlsx'!C:C,"No encontrado") -> 1405
A3: 46162 | B3: =MONTH(Tabla2[[#This Row],[Fecha]]) -> 5 | C3: Resmas | D3: =IFERROR(_xlfn.XLOOKUP(Tabla2[[#This Row],[Artículo]],Tabla1[Artículos],Tabla1[Rubro]),"") -> Librería | E3: Zicari Mariana Elena | F3: 10 | G3: unidad | H3: 5900 | I3: =Tabla2[[#This Row],[Precio Unitario ARS]]/Tabla2[[#This Row],[TC BNA]] -> 4.1549296 | J3: 0 | K3: ARS | L3: 0.21 | M3: =(Tabla2[[#This Row],[Precio Unitario ARS]]-(Tabla2[[#This Row],[Precio Unitario ARS]]*Tabla2[[#This Row],[DTO]]))*Tabla2[[#This Row],[Cantidad]] -> 59000 | N3: =Tabla2[[#This Row],[Subtotal ARS]]+(Tabla2[[#This Row],[Subtotal ARS]]*Tabla2[[#This Row],[IVA]]) -> 71390 | O3: =Tabla2[[#This Row],[TOTAL ARS]]/Tabla2[[#This Row],[TC BNA]] -> 50.274648 | P3: =_xlfn.XLOOKUP(A3,'TC_BNA xlsx'!A:A,'TC_BNA xlsx'!C:C,"No encontrado") -> 1420
A4: 46162 | B4: =MONTH(Tabla2[[#This Row],[Fecha]]) -> 5 | C4: Toner Laser HP 105 | D4: =IFERROR(_xlfn.XLOOKUP(Tabla2[[#This Row],[Artículo]],Tabla1[Artículos],Tabla1[Rubro]),"") -> Librería | E4: Zicari Mariana Elena | F4: 4 | G4: unidad | H4: 15225 | I4: =Tabla2[[#This Row],[Precio Unitario ARS]]/Tabla2[[#This Row],[TC BNA]] -> 10.721831 | J4: 0.15 | K4: ARS | L4: 0.21 | M4: =(Tabla2[[#This Row],[Precio Unitario ARS]]-(Tabla2[[#This Row],[Precio Unitario ARS]]*Tabla2[[#This Row],[DTO]]))*Tabla2[[#This Row],[Cantidad]] -> 51765 | N4: =Tabla2[[#This Row],[Subtotal ARS]]+(Tabla2[[#This Row],[Subtotal ARS]]*Tabla2[[#This Row],[IVA]]) -> 62635.65 | O4: =Tabla2[[#This Row],[TOTAL ARS]]/Tabla2[[#This Row],[TC BNA]] -> 44.109613 | P4: =_xlfn.XLOOKUP(A4,'TC_BNA xlsx'!A:A,'TC_BNA xlsx'!C:C,"No encontrado") -> 1420
A5: 46163 | B5: =MONTH(Tabla2[[#This Row],[Fecha]]) -> 5 | C5: Tuerca Flange Zinc. 1/4" | D5: =IFERROR(_xlfn.XLOOKUP(Tabla2[[#This Row],[Artículo]],Tabla1[Artículos],Tabla1[Rubro]),"") -> Reventa | E5: Distribuidora Tubulón | F5: 100800 | G5: unidad | H5: 18.78376 | I5: =Tabla2[[#This Row],[Precio Unitario ARS]]/Tabla2[[#This Row],[TC BNA]] -> 0.013321816 | J5: 0.1538 | K5: ARS | L5: 0.21 | M5: =(Tabla2[[#This Row],[Precio Unitario ARS]]-(Tabla2[[#This Row],[Precio Unitario ARS]]*Tabla2[[#This Row],[DTO]]))*Tabla2[[#This Row],[Cantidad]] -> 1602197.6 | N5: =Tabla2[[#This Row],[Subtotal ARS]]+(Tabla2[[#This Row],[Subtotal ARS]]*Tabla2[[#This Row],[IVA]]) -> 1938659.1 | O5: =Tabla2[[#This Row],[TOTAL ARS]]/Tabla2[[#This Row],[TC BNA]] -> 1374.9356 | P5: =_xlfn.XLOOKUP(A5,'TC_BNA xlsx'!A:A,'TC_BNA xlsx'!C:C,"No encontrado") -> 1410
A6: 46163 | B6: =MONTH(Tabla2[[#This Row],[Fecha]]) -> 5 | C6: Tuerca Flange Zinc. 3/8" | D6: =IFERROR(_xlfn.XLOOKUP(Tabla2[[#This Row],[Artículo]],Tabla1[Artículos],Tabla1[Rubro]),"") -> Reventa | E6: Distribuidora Tubulón | F6: 30800 | G6: unidad | H6: 38.91368 | I6: =Tabla2[[#This Row],[Precio Unitario ARS]]/Tabla2[[#This Row],[TC BNA]] -> 0.027598355 | J6: 0.1538 | K6: ARS | L6: 0.21 | M6: =(Tabla2[[#This Row],[Precio Unitario ARS]]-(Tabla2[[#This Row],[Precio Unitario ARS]]*Tabla2[[#This Row],[DTO]]))*Tabla2[[#This Row],[Cantidad]] -> 1014205.7 | N6: =Tabla2[[#This Row],[Subtotal ARS]]+(Tabla2[[#This Row],[Subtotal ARS]]*Tabla2[[#This Row],[IVA]]) -> 1227188.9 | O6: =Tabla2[[#This Row],[TOTAL ARS]]/Tabla2[[#This Row],[TC BNA]] -> 870.34672 | P6: =_xlfn.XLOOKUP(A6,'TC_BNA xlsx'!A:A,'TC_BNA xlsx'!C:C,"No encontrado") -> 1410
A7: 46163 | B7: =MONTH(Tabla2[[#This Row],[Fecha]]) -> 5 | C7: Tubo de Gas (Atal) | D7: =IFERROR(_xlfn.XLOOKUP(Tabla2[[#This Row],[Artículo]],Tabla1[Artículos],Tabla1[Rubro]),"") -> Soldadura | E7: Roberto Gustavo Q. | F7: 30 | G7: m3 | H7: 17500 | I7: =Tabla2[[#This Row],[Precio Unitario ARS]]/Tabla2[[#This Row],[TC BNA]] -> 12.411348 | J7: 0 | K7: ARS | M7: =(Tabla2[[#This Row],[Precio Unitario ARS]]-(Tabla2[[#This Row],[Precio Unitario ARS]]*Tabla2[[#This Row],[DTO]]))*Tabla2[[#This Row],[Cantidad]] -> 525000 | N7: =Tabla2[[#This Row],[Subtotal ARS]]+(Tabla2[[#This Row],[Subtotal ARS]]*Tabla2[[#This Row],[IVA]]) -> 525000 | O7: =Tabla2[[#This Row],[TOTAL ARS]]/Tabla2[[#This Row],[TC BNA]] -> 372.34043 | P7: =_xlfn.XLOOKUP(A7,'TC_BNA xlsx'!A:A,'TC_BNA xlsx'!C:C,"No encontrado") -> 1410
A8: 46163 | B8: =MONTH(Tabla2[[#This Row],[Fecha]]) -> 5 | C8: Alambre de Soldadura 0,9 mm | D8: =IFERROR(_xlfn.XLOOKUP(Tabla2[[#This Row],[Artículo]],Tabla1[Artículos],Tabla1[Rubro]),"") -> Soldadura | E8: Roberto Gustavo Q. | F8: 1 | G8: rollo | H8: 80000 | I8: =Tabla2[[#This Row],[Precio Unitario ARS]]/Tabla2[[#This Row],[TC BNA]] -> 56.737589 | J8: 0 | K8: ARS | M8: =(Tabla2[[#This Row],[Precio Unitario ARS]]-(Tabla2[[#This Row],[Precio Unitario ARS]]*Tabla2[[#This Row],[DTO]]))*Tabla2[[#This Row],[Cantidad]] -> 80000 | N8: =Tabla2[[#This Row],[Subtotal ARS]]+(Tabla2[[#This Row],[Subtotal ARS]]*Tabla2[[#This Row],[IVA]]) -> 80000 | O8: =Tabla2[[#This Row],[TOTAL ARS]]/Tabla2[[#This Row],[TC BNA]] -> 56.737589 | P8: =_xlfn.XLOOKUP(A8,'TC_BNA xlsx'!A:A,'TC_BNA xlsx'!C:C,"No encontrado") -> 1410
A9: 46164 | B9: =MONTH(Tabla2[[#This Row],[Fecha]]) -> 5 | C9: Papel higiénico Industrial | D9: =IFERROR(_xlfn.XLOOKUP(Tabla2[[#This Row],[Artículo]],Tabla1[Artículos],Tabla1[Rubro]),"") -> Limpieza | E9: Esdevi - Valeria | F9: 8 | G9: bolsa | H9: 7300 | I9: =Tabla2[[#This Row],[Precio Unitario ARS]]/Tabla2[[#This Row],[TC BNA]] -> 5.122807 | J9: 0 | K9: ARS | M9: =(Tabla2[[#This Row],[Precio Unitario ARS]]-(Tabla2[[#This Row],[Precio Unitario ARS]]*Tabla2[[#This Row],[DTO]]))*Tabla2[[#This Row],[Cantidad]] -> 58400 | N9: =Tabla2[[#This Row],[Subtotal ARS]]+(Tabla2[[#This Row],[Subtotal ARS]]*Tabla2[[#This Row],[IVA]]) -> 58400 | O9: =Tabla2[[#This Row],[TOTAL ARS]]/Tabla2[[#This Row],[TC BNA]] -> 40.982456 | P9: =_xlfn.XLOOKUP(A9,'TC_BNA xlsx'!A:A,'TC_BNA xlsx'!C:C,"No encontrado") -> 1425
A10: 46164 | B10: =MONTH(Tabla2[[#This Row],[Fecha]]) -> 5 | C10: Dispénser de rollo de cocina | D10: =IFERROR(_xlfn.XLOOKUP(Tabla2[[#This Row],[Artículo]],Tabla1[Artículos],Tabla1[Rubro]),"") -> Limpieza | E10: Esdevi - Valeria | F10: 7 | G10: bolsa | H10: 9900 | I10: =Tabla2[[#This Row],[Precio Unitario ARS]]/Tabla2[[#This Row],[TC BNA]] -> 6.9473684 | J10: 0 | K10: ARS | M10: =(Tabla2[[#This Row],[Precio Unitario ARS]]-(Tabla2[[#This Row],[Precio Unitario ARS]]*Tabla2[[#This Row],[DTO]]))*Tabla2[[#This Row],[Cantidad]] -> 69300 | N10: =Tabla2[[#This Row],[Subtotal ARS]]+(Tabla2[[#This Row],[Subtotal ARS]]*Tabla2[[#This Row],[IVA]]) -> 69300 | O10: =Tabla2[[#This Row],[TOTAL ARS]]/Tabla2[[#This Row],[TC BNA]] -> 48.631579 | P10: =_xlfn.XLOOKUP(A10,'TC_BNA xlsx'!A:A,'TC_BNA xlsx'!C:C,"No encontrado") -> 1425
A11: 46164 | B11: =MONTH(Tabla2[[#This Row],[Fecha]]) -> 5 | C11: Guantes Poli (Tactil) 8# | D11: =IFERROR(_xlfn.XLOOKUP(Tabla2[[#This Row],[Artículo]],Tabla1[Artículos],Tabla1[Rubro]),"") -> EPP | E11: Tech Safe | F11: 24 | G11: par | H11: 600 | I11: =Tabla2[[#This Row],[Precio Unitario ARS]]/Tabla2[[#This Row],[TC BNA]] -> 0.42105263 | J11: 0 | K11: ARS | L11: 0.21 | M11: =(Tabla2[[#This Row],[Precio Unitario ARS]]-(Tabla2[[#This Row],[Precio Unitario ARS]]*Tabla2[[#This Row],[DTO]]))*Tabla2[[#This Row],[Cantidad]] -> 14400 | N11: =Tabla2[[#This Row],[Subtotal ARS]]+(Tabla2[[#This Row],[Subtotal ARS]]*Tabla2[[#This Row],[IVA]]) -> 17424 | O11: =Tabla2[[#This Row],[TOTAL ARS]]/Tabla2[[#This Row],[TC BNA]] -> 12.227368 | P11: =_xlfn.XLOOKUP(A11,'TC_BNA xlsx'!A:A,'TC_BNA xlsx'!C:C,"No encontrado") -> 1425
A12: 46164 | B12: =MONTH(Tabla2[[#This Row],[Fecha]]) -> 5 | C12: Guantes Poli (Tactil) 10# | D12: =IFERROR(_xlfn.XLOOKUP(Tabla2[[#This Row],[Artículo]],Tabla1[Artículos],Tabla1[Rubro]),"") -> EPP | E12: Tech Safe | F12: 24 | G12: par | H12: 600 | I12: =Tabla2[[#This Row],[Precio Unitario ARS]]/Tabla2[[#This Row],[TC BNA]] -> 0.42105263 | J12: 0 | K12: ARS | L12: 0.21 | M12: =(Tabla2[[#This Row],[Precio Unitario ARS]]-(Tabla2[[#This Row],[Precio Unitario ARS]]*Tabla2[[#This Row],[DTO]]))*Tabla2[[#This Row],[Cantidad]] -> 14400 | N12: =Tabla2[[#This Row],[Subtotal ARS]]+(Tabla2[[#This Row],[Subtotal ARS]]*Tabla2[[#This Row],[IVA]]) -> 17424 | O12: =Tabla2[[#This Row],[TOTAL ARS]]/Tabla2[[#This Row],[TC BNA]] -> 12.227368 | P12: =_xlfn.XLOOKUP(A12,'TC_BNA xlsx'!A:A,'TC_BNA xlsx'!C:C,"No encontrado") -> 1425
A13: 46164 | B13: =MONTH(Tabla2[[#This Row],[Fecha]]) -> 5 | C13: Guantes Dyne 5 | D13: =IFERROR(_xlfn.XLOOKUP(Tabla2[[#This Row],[Artículo]],Tabla1[Artículos],Tabla1[Rubro]),"") -> EPP | E13: Tech Safe | F13: 12 | G13: par | H13: 4295 | I13: =Tabla2[[#This Row],[Precio Unitario ARS]]/Tabla2[[#This Row],[TC BNA]] -> 3.0140351 | J13: 0 | K13: ARS | L13: 0.21 | M13: =(Tabla2[[#This Row],[Precio Unitario ARS]]-(Tabla2[[#This Row],[Precio Unitario ARS]]*Tabla2[[#This Row],[DTO]]))*Tabla2[[#This Row],[Cantidad]] -> 51540 | N13: =Tabla2[[#This Row],[Subtotal ARS]]+(Tabla2[[#This Row],[Subtotal ARS]]*Tabla2[[#This Row],[IVA]]) -> 62363.4 | O13: =Tabla2[[#This Row],[TOTAL ARS]]/Tabla2[[#This Row],[TC BNA]] -> 43.763789 | P13: =_xlfn.XLOOKUP(A13,'TC_BNA xlsx'!A:A,'TC_BNA xlsx'!C:C,"No encontrado") -> 1425
A14: 46168 | B14: =MONTH(Tabla2[[#This Row],[Fecha]]) -> 5 | C14: Arandela Plana Zinc. 1/4" | D14: =IFERROR(_xlfn.XLOOKUP(Tabla2[[#This Row],[Artículo]],Tabla1[Artículos],Tabla1[Rubro]),"") -> Reventa | E14: Disur | F14: 63.5 | G14: kg | H14: 4800 | I14: =Tabla2[[#This Row],[Precio Unitario ARS]]/Tabla2[[#This Row],[TC BNA]] -> 3.3566434 | J14: 0 | K14: ARS | L14: 0.21 | M14: =(Tabla2[[#This Row],[Precio Unitario ARS]]-(Tabla2[[#This Row],[Precio Unitario ARS]]*Tabla2[[#This Row],[DTO]]))*Tabla2[[#This Row],[Cantidad]] -> 304800 | N14: =Tabla2[[#This Row],[Subtotal ARS]]+(Tabla2[[#This Row],[Subtotal ARS]]*Tabla2[[#This Row],[IVA]]) -> 368808 | O14: =Tabla2[[#This Row],[TOTAL ARS]]/Tabla2[[#This Row],[TC BNA]] -> 257.90769 | P14: =_xlfn.XLOOKUP(A14,'TC_BNA xlsx'!A:A,'TC_BNA xlsx'!C:C,"No encontrado") -> 1430
A15: 46168 | B15: =MONTH(Tabla2[[#This Row],[Fecha]]) -> 5 | C15: Arandela Plana Zinc. 3/8" | D15: =IFERROR(_xlfn.XLOOKUP(Tabla2[[#This Row],[Artículo]],Tabla1[Artículos],Tabla1[Rubro]),"") -> Reventa | E15: Disur | F15: 50 | G15: kg | H15: 4185 | I15: =Tabla2[[#This Row],[Precio Unitario ARS]]/Tabla2[[#This Row],[TC BNA]] -> 2.9265734 | J15: 0 | K15: ARS | L15: 0.21 | M15: =(Tabla2[[#This Row],[Precio Unitario ARS]]-(Tabla2[[#This Row],[Precio Unitario ARS]]*Tabla2[[#This Row],[DTO]]))*Tabla2[[#This Row],[Cantidad]] -> 209250 | N15: =Tabla2[[#This Row],[Subtotal ARS]]+(Tabla2[[#This Row],[Subtotal ARS]]*Tabla2[[#This Row],[IVA]]) -> 253192.5 | O15: =Tabla2[[#This Row],[TOTAL ARS]]/Tabla2[[#This Row],[TC BNA]] -> 177.05769 | P15: =_xlfn.XLOOKUP(A15,'TC_BNA xlsx'!A:A,'TC_BNA xlsx'!C:C,"No encontrado") -> 1430
A16: 46168 | B16: =MONTH(Tabla2[[#This Row],[Fecha]]) -> 5 | C16: Arandela Plana Zinc. 5/16" | D16: =IFERROR(_xlfn.XLOOKUP(Tabla2[[#This Row],[Artículo]],Tabla1[Artículos],Tabla1[Rubro]),"") -> Reventa | E16: Disur | F16: 35 | G16: kg | H16: 4890 | I16: =Tabla2[[#This Row],[Precio Unitario ARS]]/Tabla2[[#This Row],[TC BNA]] -> 3.4195804 | J16: 0 | K16: ARS | L16: 0.21 | M16: =(Tabla2[[#This Row],[Precio Unitario ARS]]-(Tabla2[[#This Row],[Precio Unitario ARS]]*Tabla2[[#This Row],[DTO]]))*Tabla2[[#This Row],[Cantidad]] -> 171150 | N16: =Tabla2[[#This Row],[Subtotal ARS]]+(Tabla2[[#This Row],[Subtotal ARS]]*Tabla2[[#This Row],[IVA]]) -> 207091.5 | O16: =Tabla2[[#This Row],[TOTAL ARS]]/Tabla2[[#This Row],[TC BNA]] -> 144.81923 | P16: =_xlfn.XLOOKUP(A16,'TC_BNA xlsx'!A:A,'TC_BNA xlsx'!C:C,"No encontrado") -> 1430
A17: 46168 | B17: =MONTH(Tabla2[[#This Row],[Fecha]]) -> 5 | C17: Tor. Cab. Re. 1/4" | D17: =IFERROR(_xlfn.XLOOKUP(Tabla2[[#This Row],[Artículo]],Tabla1[Artículos],Tabla1[Rubro]),"") -> Reventa | E17: Disur | F17: 10000 | G17: unidad | H17: 29.2 | I17: =Tabla2[[#This Row],[Precio Unitario ARS]]/Tabla2[[#This Row],[TC BNA]] -> 0.02041958 | J17: 0 | K17: ARS | L17: 0.21 | M17: =(Tabla2[[#This Row],[Precio Unitario ARS]]-(Tabla2[[#This Row],[Precio Unitario ARS]]*Tabla2[[#This Row],[DTO]]))*Tabla2[[#This Row],[Cantidad]] -> 292000 | N17: =Tabla2[[#This Row],[Subtotal ARS]]+(Tabla2[[#This Row],[Subtotal ARS]]*Tabla2[[#This Row],[IVA]]) -> 353320 | O17: =Tabla2[[#This Row],[TOTAL ARS]]/Tabla2[[#This Row],[TC BNA]] -> 247.07692 | P17: =_xlfn.XLOOKUP(A17,'TC_BNA xlsx'!A:A,'TC_BNA xlsx'!C:C,"No encontrado") -> 1430
A18: 46168 | B18: =MONTH(Tabla2[[#This Row],[Fecha]]) -> 5 | C18: Tor. Traba 1/4" | D18: =IFERROR(_xlfn.XLOOKUP(Tabla2[[#This Row],[Artículo]],Tabla1[Artículos],Tabla1[Rubro]),"") -> Reventa | E18: Disur | F18: 60000 | G18: unidad | H18: 27.97 | I18: =Tabla2[[#This Row],[Precio Unitario ARS]]/Tabla2[[#This Row],[TC BNA]] -> 0.019559441 | J18: 0 | K18: ARS | L18: 0.21 | M18: =(Tabla2[[#This Row],[Precio Unitario ARS]]-(Tabla2[[#This Row],[Precio Unitario ARS]]*Tabla2[[#This Row],[DTO]]))*Tabla2[[#This Row],[Cantidad]] -> 1678200 | N18: =Tabla2[[#This Row],[Subtotal ARS]]+(Tabla2[[#This Row],[Subtotal ARS]]*Tabla2[[#This Row],[IVA]]) -> 2030622 | O18: =Tabla2[[#This Row],[TOTAL ARS]]/Tabla2[[#This Row],[TC BNA]] -> 1420.0154 | P18: =_xlfn.XLOOKUP(A18,'TC_BNA xlsx'!A:A,'TC_BNA xlsx'!C:C,"No encontrado") -> 1430
A19: 46168 | B19: =MONTH(Tabla2[[#This Row],[Fecha]]) -> 5 | C19: Tuerca Zinc. 1/4" | D19: =IFERROR(_xlfn.XLOOKUP(Tabla2[[#This Row],[Artículo]],Tabla1[Artículos],Tabla1[Rubro]),"") -> Reventa | E19: Disur | F19: 20000 | G19: unidad | H19: 12.5 | I19: =Tabla2[[#This Row],[Precio Unitario ARS]]/Tabla2[[#This Row],[TC BNA]] -> 0.0087412587 | J19: 0 | K19: ARS | L19: 0.21 | M19: =(Tabla2[[#This Row],[Precio Unitario ARS]]-(Tabla2[[#This Row],[Precio Unitario ARS]]*Tabla2[[#This Row],[DTO]]))*Tabla2[[#This Row],[Cantidad]] -> 250000 | N19: =Tabla2[[#This Row],[Subtotal ARS]]+(Tabla2[[#This Row],[Subtotal ARS]]*Tabla2[[#This Row],[IVA]]) -> 302500 | O19: =Tabla2[[#This Row],[TOTAL ARS]]/Tabla2[[#This Row],[TC BNA]] -> 211.53846 | P19: =_xlfn.XLOOKUP(A19,'TC_BNA xlsx'!A:A,'TC_BNA xlsx'!C:C,"No encontrado") -> 1430
A20: 46168 | B20: =MONTH(Tabla2[[#This Row],[Fecha]]) -> 5 | C20: Tuerca Zinc. 3/8" | D20: =IFERROR(_xlfn.XLOOKUP(Tabla2[[#This Row],[Artículo]],Tabla1[Artículos],Tabla1[Rubro]),"") -> Reventa | E20: Disur | F20: 6800 | G20: unidad | H20: 26 | I20: =Tabla2[[#This Row],[Precio Unitario ARS]]/Tabla2[[#This Row],[TC BNA]] -> 0.018181818 | J20: 0 | K20: ARS | L20: 0.21 | M20: =(Tabla2[[#This Row],[Precio Unitario ARS]]-(Tabla2[[#This Row],[Precio Unitario ARS]]*Tabla2[[#This Row],[DTO]]))*Tabla2[[#This Row],[Cantidad]] -> 176800 | N20: =Tabla2[[#This Row],[Subtotal ARS]]+(Tabla2[[#This Row],[Subtotal ARS]]*Tabla2[[#This Row],[IVA]]) -> 213928 | O20: =Tabla2[[#This Row],[TOTAL ARS]]/Tabla2[[#This Row],[TC BNA]] -> 149.6 | P20: =_xlfn.XLOOKUP(A20,'TC_BNA xlsx'!A:A,'TC_BNA xlsx'!C:C,"No encontrado") -> 1430
A21: 46168 | B21: =MONTH(Tabla2[[#This Row],[Fecha]]) -> 5 | C21: Tuerca Zinc. 5/16" | D21: =IFERROR(_xlfn.XLOOKUP(Tabla2[[#This Row],[Artículo]],Tabla1[Artículos],Tabla1[Rubro]),"") -> Reventa | E21: Disur | F21: 6000 | G21: unidad | H21: 18.6 | I21: =Tabla2[[#This Row],[Precio Unitario ARS]]/Tabla2[[#This Row],[TC BNA]] -> 0.013006993 | J21: 0 | K21: ARS | L21: 0.21 | M21: =(Tabla2[[#This Row],[Precio Unitario ARS]]-(Tabla2[[#This Row],[Precio Unitario ARS]]*Tabla2[[#This Row],[DTO]]))*Tabla2[[#This Row],[Cantidad]] -> 111600 | N21: =Tabla2[[#This Row],[Subtotal ARS]]+(Tabla2[[#This Row],[Subtotal ARS]]*Tabla2[[#This Row],[IVA]]) -> 135036 | O21: =Tabla2[[#This Row],[TOTAL ARS]]/Tabla2[[#This Row],[TC BNA]] -> 94.430769 | P21: =_xlfn.XLOOKUP(A21,'TC_BNA xlsx'!A:A,'TC_BNA xlsx'!C:C,"No encontrado") -> 1430
A22: 46168 | B22: =MONTH(Tabla2[[#This Row],[Fecha]]) -> 5 | C22: Lysoform | D22: =IFERROR(_xlfn.XLOOKUP(Tabla2[[#This Row],[Artículo]],Tabla1[Artículos],Tabla1[Rubro]),"") -> Limpieza | E22: Imperio de la Limpieza | F22: 10 | G22: unidad | H22: 3619.83 | I22: =Tabla2[[#This Row],[Precio Unitario ARS]]/Tabla2[[#This Row],[TC BNA]] -> 2.5313497 | J22: 0 | K22: ARS | L22: 0.21 | M22: =(Tabla2[[#This Row],[Precio Unitario ARS]]-(Tabla2[[#This Row],[Precio Unitario ARS]]*Tabla2[[#This Row],[DTO]]))*Tabla2[[#This Row],[Cantidad]] -> 36198.3 | N22: =Tabla2[[#This Row],[Subtotal ARS]]+(Tabla2[[#This Row],[Subtotal ARS]]*Tabla2[[#This Row],[IVA]]) -> 43799.943 | O22: =Tabla2[[#This Row],[TOTAL ARS]]/Tabla2[[#This Row],[TC BNA]] -> 30.629331 | P22: =_xlfn.XLOOKUP(A22,'TC_BNA xlsx'!A:A,'TC_BNA xlsx'!C:C,"No encontrado") -> 1430
A23: 46168 | B23: =MONTH(Tabla2[[#This Row],[Fecha]]) -> 5 | C23: Bolsas 50x70 | D23: =IFERROR(_xlfn.XLOOKUP(Tabla2[[#This Row],[Artículo]],Tabla1[Artículos],Tabla1[Rubro]),"") -> Limpieza | E23: Imperio de la Limpieza | F23: 130 | G23: unidad | H23: =611.57/10 -> 61.157 | I23: =Tabla2[[#This Row],[Precio Unitario ARS]]/Tabla2[[#This Row],[TC BNA]] -> 0.042767133 | J23: 0 | K23: ARS | L23: 0.21 | M23: =(Tabla2[[#This Row],[Precio Unitario ARS]]-(Tabla2[[#This Row],[Precio Unitario ARS]]*Tabla2[[#This Row],[DTO]]))*Tabla2[[#This Row],[Cantidad]] -> 7950.41 | N23: =Tabla2[[#This Row],[Subtotal ARS]]+(Tabla2[[#This Row],[Subtotal ARS]]*Tabla2[[#This Row],[IVA]]) -> 9619.9961 | O23: =Tabla2[[#This Row],[TOTAL ARS]]/Tabla2[[#This Row],[TC BNA]] -> 6.72727 | P23: =_xlfn.XLOOKUP(A23,'TC_BNA xlsx'!A:A,'TC_BNA xlsx'!C:C,"No encontrado") -> 1430
A24: 46168 | B24: =MONTH(Tabla2[[#This Row],[Fecha]]) -> 5 | C24: Bolsas 80x110 | D24: =IFERROR(_xlfn.XLOOKUP(Tabla2[[#This Row],[Artículo]],Tabla1[Artículos],Tabla1[Rubro]),"") -> Limpieza | E24: Imperio de la Limpieza | F24: 110 | G24: unidad | H24: =1876.03/10 -> 187.603 | I24: =Tabla2[[#This Row],[Precio Unitario ARS]]/Tabla2[[#This Row],[TC BNA]] -> 0.13119091 | J24: 0 | K24: ARS | L24: 0.21 | M24: =(Tabla2[[#This Row],[Precio Unitario ARS]]-(Tabla2[[#This Row],[Precio Unitario ARS]]*Tabla2[[#This Row],[DTO]]))*Tabla2[[#This Row],[Cantidad]] -> 20636.33 | N24: =Tabla2[[#This Row],[Subtotal ARS]]+(Tabla2[[#This Row],[Subtotal ARS]]*Tabla2[[#This Row],[IVA]]) -> 24969.959 | O24: =Tabla2[[#This Row],[TOTAL ARS]]/Tabla2[[#This Row],[TC BNA]] -> 17.46151 | P24: =_xlfn.XLOOKUP(A24,'TC_BNA xlsx'!A:A,'TC_BNA xlsx'!C:C,"No encontrado") -> 1430
A25: 46168 | B25: =MONTH(Tabla2[[#This Row],[Fecha]]) -> 5 | C25: Esponjas | D25: =IFERROR(_xlfn.XLOOKUP(Tabla2[[#This Row],[Artículo]],Tabla1[Artículos],Tabla1[Rubro]),"") -> Limpieza | E25: Imperio de la Limpieza | F25: 6 | G25: unidad | H25: 520.66 | I25: =Tabla2[[#This Row],[Precio Unitario ARS]]/Tabla2[[#This Row],[TC BNA]] -> 0.3640979 | J25: 0 | K25: ARS | L25: 0.21 | M25: =(Tabla2[[#This Row],[Precio Unitario ARS]]-(Tabla2[[#This Row],[Precio Unitario ARS]]*Tabla2[[#This Row],[DTO]]))*Tabla2[[#This Row],[Cantidad]] -> 3123.96 | N25: =Tabla2[[#This Row],[Subtotal ARS]]+(Tabla2[[#This Row],[Subtotal ARS]]*Tabla2[[#This Row],[IVA]]) -> 3779.9916 | O25: =Tabla2[[#This Row],[TOTAL ARS]]/Tabla2[[#This Row],[TC BNA]] -> 2.6433508 | P25: =_xlfn.XLOOKUP(A25,'TC_BNA xlsx'!A:A,'TC_BNA xlsx'!C:C,"No encontrado") -> 1430
A26: 46168 | B26: =MONTH(Tabla2[[#This Row],[Fecha]]) -> 5 | C26: Desodorante p/piso Lavanda | D26: =IFERROR(_xlfn.XLOOKUP(Tabla2[[#This Row],[Artículo]],Tabla1[Artículos],Tabla1[Rubro]),"") -> Limpieza | E26: Imperio de la Limpieza | F26: 5 | G26: litro | H26: =2809.91/5 -> 561.982 | I26: =Tabla2[[#This Row],[Precio Unitario ARS]]/Tabla2[[#This Row],[TC BNA]] -> 0.39299441 | J26: 0 | K26: ARS | L26: 0.21 | M26: =(Tabla2[[#This Row],[Precio Unitario ARS]]-(Tabla2[[#This Row],[Precio Unitario ARS]]*Tabla2[[#This Row],[DTO]]))*Tabla2[[#This Row],[Cantidad]] -> 2809.91 | N26: =Tabla2[[#This Row],[Subtotal ARS]]+(Tabla2[[#This Row],[Subtotal ARS]]*Tabla2[[#This Row],[IVA]]) -> 3399.9911 | O26: =Tabla2[[#This Row],[TOTAL ARS]]/Tabla2[[#This Row],[TC BNA]] -> 2.3776162 | P26: =_xlfn.XLOOKUP(A26,'TC_BNA xlsx'!A:A,'TC_BNA xlsx'!C:C,"No encontrado") -> 1430
A27: 46168 | B27: =MONTH(Tabla2[[#This Row],[Fecha]]) -> 5 | C27: Guantes de limpieza (Talle L) | D27: =IFERROR(_xlfn.XLOOKUP(Tabla2[[#This Row],[Artículo]],Tabla1[Artículos],Tabla1[Rubro]),"") -> Limpieza | E27: Imperio de la Limpieza | F27: 1 | G27: unidad | H27: 2917.35 | I27: =Tabla2[[#This Row],[Precio Unitario ARS]]/Tabla2[[#This Row],[TC BNA]] -> 2.0401049 | J27: 0 | K27: ARS | L27: 0.21 | M27: =(Tabla2[[#This Row],[Precio Unitario ARS]]-(Tabla2[[#This Row],[Precio Unitario ARS]]*Tabla2[[#This Row],[DTO]]))*Tabla2[[#This Row],[Cantidad]] -> 2917.35 | N27: =Tabla2[[#This Row],[Subtotal ARS]]+(Tabla2[[#This Row],[Subtotal ARS]]*Tabla2[[#This Row],[IVA]]) -> 3529.9935 | O27: =Tabla2[[#This Row],[TOTAL ARS]]/Tabla2[[#This Row],[TC BNA]] -> 2.4685269 | P27: =_xlfn.XLOOKUP(A27,'TC_BNA xlsx'!A:A,'TC_BNA xlsx'!C:C,"No encontrado") -> 1430
A28: 46168 | B28: =MONTH(Tabla2[[#This Row],[Fecha]]) -> 5 | C28: Jabón líquido | D28: =IFERROR(_xlfn.XLOOKUP(Tabla2[[#This Row],[Artículo]],Tabla1[Artículos],Tabla1[Rubro]),"") -> Limpieza | E28: Imperio de la Limpieza | F28: 5 | G28: litro | H28: =8462.8/5 -> 1692.56 | I28: =Tabla2[[#This Row],[Precio Unitario ARS]]/Tabla2[[#This Row],[TC BNA]] -> 1.1836084 | J28: 0 | K28: ARS | L28: 0.21 | M28: =(Tabla2[[#This Row],[Precio Unitario ARS]]-(Tabla2[[#This Row],[Precio Unitario ARS]]*Tabla2[[#This Row],[DTO]]))*Tabla2[[#This Row],[Cantidad]] -> 8462.8 | N28: =Tabla2[[#This Row],[Subtotal ARS]]+(Tabla2[[#This Row],[Subtotal ARS]]*Tabla2[[#This Row],[IVA]]) -> 10239.988 | O28: =Tabla2[[#This Row],[TOTAL ARS]]/Tabla2[[#This Row],[TC BNA]] -> 7.1608308 | P28: =_xlfn.XLOOKUP(A28,'TC_BNA xlsx'!A:A,'TC_BNA xlsx'!C:C,"No encontrado") -> 1430
A29: 46168 | B29: =MONTH(Tabla2[[#This Row],[Fecha]]) -> 5 | C29: Detergente | D29: =IFERROR(_xlfn.XLOOKUP(Tabla2[[#This Row],[Artículo]],Tabla1[Artículos],Tabla1[Rubro]),"") -> Limpieza | E29: Imperio de la Limpieza | F29: 5 | G29: litro | H29: =8239.66/5 -> 1647.932 | I29: =Tabla2[[#This Row],[Precio Unitario ARS]]/Tabla2[[#This Row],[TC BNA]] -> 1.1524 | J29: 0 | K29: ARS | L29: 0.21 | M29: =(Tabla2[[#This Row],[Precio Unitario ARS]]-(Tabla2[[#This Row],[Precio Unitario ARS]]*Tabla2[[#This Row],[DTO]]))*Tabla2[[#This Row],[Cantidad]] -> 8239.66 | N29: =Tabla2[[#This Row],[Subtotal ARS]]+(Tabla2[[#This Row],[Subtotal ARS]]*Tabla2[[#This Row],[IVA]]) -> 9969.9886 | O29: =Tabla2[[#This Row],[TOTAL ARS]]/Tabla2[[#This Row],[TC BNA]] -> 6.97202 | P29: =_xlfn.XLOOKUP(A29,'TC_BNA xlsx'!A:A,'TC_BNA xlsx'!C:C,"No encontrado") -> 1430
A30: 46168 | B30: =MONTH(Tabla2[[#This Row],[Fecha]]) -> 5 | C30: Rejilla | D30: =IFERROR(_xlfn.XLOOKUP(Tabla2[[#This Row],[Artículo]],Tabla1[Artículos],Tabla1[Rubro]),"") -> Limpieza | E30: Imperio de la Limpieza | F30: 2 | G30: unidad | H30: 710.74 | I30: =Tabla2[[#This Row],[Precio Unitario ARS]]/Tabla2[[#This Row],[TC BNA]] -> 0.49702098 | J30: 0 | K30: ARS | L30: 0.21 | M30: =(Tabla2[[#This Row],[Precio Unitario ARS]]-(Tabla2[[#This Row],[Precio Unitario ARS]]*Tabla2[[#This Row],[DTO]]))*Tabla2[[#This Row],[Cantidad]] -> 1421.48 | N30: =Tabla2[[#This Row],[Subtotal ARS]]+(Tabla2[[#This Row],[Subtotal ARS]]*Tabla2[[#This Row],[IVA]]) -> 1719.9908 | O30: =Tabla2[[#This Row],[TOTAL ARS]]/Tabla2[[#This Row],[TC BNA]] -> 1.2027908 | P30: =_xlfn.XLOOKUP(A30,'TC_BNA xlsx'!A:A,'TC_BNA xlsx'!C:C,"No encontrado") -> 1430
A31: 46168 | B31: =MONTH(Tabla2[[#This Row],[Fecha]]) -> 5 | C31: Trapo de piso | D31: =IFERROR(_xlfn.XLOOKUP(Tabla2[[#This Row],[Artículo]],Tabla1[Artículos],Tabla1[Rubro]),"") -> Limpieza | E31: Imperio de la Limpieza | F31: 4 | G31: unidad | H31: 1661.15 | I31: =Tabla2[[#This Row],[Precio Unitario ARS]]/Tabla2[[#This Row],[TC BNA]] -> 1.1616434 | J31: 0 | K31: ARS | L31: 0.21 | M31: =(Tabla2[[#This Row],[Precio Unitario ARS]]-(Tabla2[[#This Row],[Precio Unitario ARS]]*Tabla2[[#This Row],[DTO]]))*Tabla2[[#This Row],[Cantidad]] -> 6644.6 | N31: =Tabla2[[#This Row],[Subtotal ARS]]+(Tabla2[[#This Row],[Subtotal ARS]]*Tabla2[[#This Row],[IVA]]) -> 8039.966 | O31: =Tabla2[[#This Row],[TOTAL ARS]]/Tabla2[[#This Row],[TC BNA]] -> 5.6223538 | P31: =_xlfn.XLOOKUP(A31,'TC_BNA xlsx'!A:A,'TC_BNA xlsx'!C:C,"No encontrado") -> 1430
A32: 46168 | B32: =MONTH(Tabla2[[#This Row],[Fecha]]) -> 5 | C32: Saphirus | D32: =IFERROR(_xlfn.XLOOKUP(Tabla2[[#This Row],[Artículo]],Tabla1[Artículos],Tabla1[Rubro]),"") -> Limpieza | E32: Imperio de la Limpieza | F32: 7 | G32: unidad | H32: 4818.18 | I32: =Tabla2[[#This Row],[Precio Unitario ARS]]/Tabla2[[#This Row],[TC BNA]] -> 3.3693566 | J32: 0 | K32: ARS | L32: 0.21 | M32: =(Tabla2[[#This Row],[Precio Unitario ARS]]-(Tabla2[[#This Row],[Precio Unitario ARS]]*Tabla2[[#This Row],[DTO]]))*Tabla2[[#This Row],[Cantidad]] -> 33727.26 | N32: =Tabla2[[#This Row],[Subtotal ARS]]+(Tabla2[[#This Row],[Subtotal ARS]]*Tabla2[[#This Row],[IVA]]) -> 40809.985 | O32: =Tabla2[[#This Row],[TOTAL ARS]]/Tabla2[[#This Row],[TC BNA]] -> 28.538451 | P32: =_xlfn.XLOOKUP(A32,'TC_BNA xlsx'!A:A,'TC_BNA xlsx'!C:C,"No encontrado") -> 1430
A33: 46168 | B33: =MONTH(Tabla2[[#This Row],[Fecha]]) -> 5 | C33: Esponja tipo patito | D33: =IFERROR(_xlfn.XLOOKUP(Tabla2[[#This Row],[Artículo]],Tabla1[Artículos],Tabla1[Rubro]),"") -> Limpieza | E33: Imperio de la Limpieza | F33: 2 | G33: unidad | H33: 719 | I33: =Tabla2[[#This Row],[Precio Unitario ARS]]/Tabla2[[#This Row],[TC BNA]] -> 0.5027972 | J33: 0 | K33: ARS | L33: 0.21 | M33: =(Tabla2[[#This Row],[Precio Unitario ARS]]-(Tabla2[[#This Row],[Precio Unitario ARS]]*Tabla2[[#This Row],[DTO]]))*Tabla2[[#This Row],[Cantidad]] -> 1438 | N33: =Tabla2[[#This Row],[Subtotal ARS]]+(Tabla2[[#This Row],[Subtotal ARS]]*Tabla2[[#This Row],[IVA]]) -> 1739.98 | O33: =Tabla2[[#This Row],[TOTAL ARS]]/Tabla2[[#This Row],[TC BNA]] -> 1.2167692 | P33: =_xlfn.XLOOKUP(A33,'TC_BNA xlsx'!A:A,'TC_BNA xlsx'!C:C,"No encontrado") -> 1430
A34: 46169 | B34: =MONTH(Tabla2[[#This Row],[Fecha]]) -> 5 | C34: EU-250 | D34: =IFERROR(_xlfn.XLOOKUP(Tabla2[[#This Row],[Artículo]],Tabla1[Artículos],Tabla1[Rubro]),"") -> Servicio | E34: MTZ | F34: 726 | G34: unidad | H34: 517 | I34: =Tabla2[[#This Row],[Precio Unitario ARS]]/Tabla2[[#This Row],[TC BNA]] -> 0.36153846 | J34: 0 | K34: ARS | M34: =(Tabla2[[#This Row],[Precio Unitario ARS]]-(Tabla2[[#This Row],[Precio Unitario ARS]]*Tabla2[[#This Row],[DTO]]))*Tabla2[[#This Row],[Cantidad]] -> 375342 | N34: =Tabla2[[#This Row],[Subtotal ARS]]+(Tabla2[[#This Row],[Subtotal ARS]]*Tabla2[[#This Row],[IVA]]) -> 375342 | O34: =Tabla2[[#This Row],[TOTAL ARS]]/Tabla2[[#This Row],[TC BNA]] -> 262.47692 | P34: =_xlfn.XLOOKUP(A34,'TC_BNA xlsx'!A:A,'TC_BNA xlsx'!C:C,"No encontrado") -> 1430
A35: 46169 | B35: =MONTH(Tabla2[[#This Row],[Fecha]]) -> 5 | C35: EU-300 | D35: =IFERROR(_xlfn.XLOOKUP(Tabla2[[#This Row],[Artículo]],Tabla1[Artículos],Tabla1[Rubro]),"") -> Servicio | E35: MTZ | F35: 1800 | G35: unidad | H35: 620 | I35: =Tabla2[[#This Row],[Precio Unitario ARS]]/Tabla2[[#This Row],[TC BNA]] -> 0.43356643 | J35: 0 | K35: ARS | M35: =(Tabla2[[#This Row],[Precio Unitario ARS]]-(Tabla2[[#This Row],[Precio Unitario ARS]]*Tabla2[[#This Row],[DTO]]))*Tabla2[[#This Row],[Cantidad]] -> 1116000 | N35: =Tabla2[[#This Row],[Subtotal ARS]]+(Tabla2[[#This Row],[Subtotal ARS]]*Tabla2[[#This Row],[IVA]]) -> 1116000 | O35: =Tabla2[[#This Row],[TOTAL ARS]]/Tabla2[[#This Row],[TC BNA]] -> 780.41958 | P35: =_xlfn.XLOOKUP(A35,'TC_BNA xlsx'!A:A,'TC_BNA xlsx'!C:C,"No encontrado") -> 1430
A36: 46170 | B36: =MONTH(Tabla2[[#This Row],[Fecha]]) -> 5 | C36: Pallets | D36: =IFERROR(_xlfn.XLOOKUP(Tabla2[[#This Row],[Artículo]],Tabla1[Artículos],Tabla1[Rubro]),"") -> Embalaje | E36: Pallets Buenos Aires | F36: 20 | G36: unidad | H36: 6500 | I36: =Tabla2[[#This Row],[Precio Unitario ARS]]/Tabla2[[#This Row],[TC BNA]] -> 4.5454545 | J36: 0 | K36: ARS | L36: 0.21 | M36: =(Tabla2[[#This Row],[Precio Unitario ARS]]-(Tabla2[[#This Row],[Precio Unitario ARS]]*Tabla2[[#This Row],[DTO]]))*Tabla2[[#This Row],[Cantidad]] -> 130000 | N36: =Tabla2[[#This Row],[Subtotal ARS]]+(Tabla2[[#This Row],[Subtotal ARS]]*Tabla2[[#This Row],[IVA]]) -> 157300 | O36: =Tabla2[[#This Row],[TOTAL ARS]]/Tabla2[[#This Row],[TC BNA]] -> 110 | P36: =_xlfn.XLOOKUP(A36,'TC_BNA xlsx'!A:A,'TC_BNA xlsx'!C:C,"No encontrado") -> 1430
A37: 46170 | B37: =MONTH(Tabla2[[#This Row],[Fecha]]) -> 5 | C37: Stretch 10 cm | D37: =IFERROR(_xlfn.XLOOKUP(Tabla2[[#This Row],[Artículo]],Tabla1[Artículos],Tabla1[Rubro]),"") -> Embalaje | E37: Mad Packaging | F37: 187 | G37: kg | H37: 4592 | I37: =Tabla2[[#This Row],[Precio Unitario ARS]]/Tabla2[[#This Row],[TC BNA]] -> 3.2111888 | J37: 0 | K37: ARS | L37: 0.21 | M37: =(Tabla2[[#This Row],[Precio Unitario ARS]]-(Tabla2[[#This Row],[Precio Unitario ARS]]*Tabla2[[#This Row],[DTO]]))*Tabla2[[#This Row],[Cantidad]] -> 858704 | N37: =Tabla2[[#This Row],[Subtotal ARS]]+(Tabla2[[#This Row],[Subtotal ARS]]*Tabla2[[#This Row],[IVA]]) -> 1039031.8 | O37: =Tabla2[[#This Row],[TOTAL ARS]]/Tabla2[[#This Row],[TC BNA]] -> 726.59569 | P37: =_xlfn.XLOOKUP(A37,'TC_BNA xlsx'!A:A,'TC_BNA xlsx'!C:C,"No encontrado") -> 1430 | Q37: Tomaron TC 1435
A38: 46170 | B38: =MONTH(Tabla2[[#This Row],[Fecha]]) -> 5 | C38: Stretch 50 cm C/Mango | D38: =IFERROR(_xlfn.XLOOKUP(Tabla2[[#This Row],[Artículo]],Tabla1[Artículos],Tabla1[Rubro]),"") -> Embalaje | E38: Mad Packaging | F38: 31 | G38: kg | H38: 4547.6 | I38: =Tabla2[[#This Row],[Precio Unitario ARS]]/Tabla2[[#This Row],[TC BNA]] -> 3.1801399 | J38: 0 | K38: ARS | L38: 0.21 | M38: =(Tabla2[[#This Row],[Precio Unitario ARS]]-(Tabla2[[#This Row],[Precio Unitario ARS]]*Tabla2[[#This Row],[DTO]]))*Tabla2[[#This Row],[Cantidad]] -> 140975.6 | N38: =Tabla2[[#This Row],[Subtotal ARS]]+(Tabla2[[#This Row],[Subtotal ARS]]*Tabla2[[#This Row],[IVA]]) -> 170580.48 | O38: =Tabla2[[#This Row],[TOTAL ARS]]/Tabla2[[#This Row],[TC BNA]] -> 119.28705 | P38: =_xlfn.XLOOKUP(A38,'TC_BNA xlsx'!A:A,'TC_BNA xlsx'!C:C,"No encontrado") -> 1430
A39: 46170 | B39: =MONTH(Tabla2[[#This Row],[Fecha]]) -> 5 | C39: Precintos 450 x 10 | D39: =IFERROR(_xlfn.XLOOKUP(Tabla2[[#This Row],[Artículo]],Tabla1[Artículos],Tabla1[Rubro]),"") -> Embalaje | E39: Adamat | F39: 20 | G39: bolsa | H39: 22056.94 | I39: =Tabla2[[#This Row],[Precio Unitario ARS]]/Tabla2[[#This Row],[TC BNA]] -> 15.424434 | J39: 0.4 | K39: ARS | L39: 0.21 | M39: =(Tabla2[[#This Row],[Precio Unitario ARS]]-(Tabla2[[#This Row],[Precio Unitario ARS]]*Tabla2[[#This Row],[DTO]]))*Tabla2[[#This Row],[Cantidad]] -> 264683.28 | N39: =Tabla2[[#This Row],[Subtotal ARS]]+(Tabla2[[#This Row],[Subtotal ARS]]*Tabla2[[#This Row],[IVA]]) -> 320266.77 | O39: =Tabla2[[#This Row],[TOTAL ARS]]/Tabla2[[#This Row],[TC BNA]] -> 223.96278 | P39: =_xlfn.XLOOKUP(A39,'TC_BNA xlsx'!A:A,'TC_BNA xlsx'!C:C,"No encontrado") -> 1430
A40: 46170 | B40: =MONTH(Tabla2[[#This Row],[Fecha]]) -> 5 | C40: Casco S/Arnes Blanco | D40: =IFERROR(_xlfn.XLOOKUP(Tabla2[[#This Row],[Artículo]],Tabla1[Artículos],Tabla1[Rubro]),"") -> EPP | E40: Roguant | F40: 2 | G40: unidad | H40: =2.77*1430 -> 3961.1 | I40: =Tabla2[[#This Row],[Precio Unitario ARS]]/Tabla2[[#This Row],[TC BNA]] -> 2.77 | J40: 0 | K40: ARS | L40: 0.21 | M40: =(Tabla2[[#This Row],[Precio Unitario ARS]]-(Tabla2[[#This Row],[Precio Unitario ARS]]*Tabla2[[#This Row],[DTO]]))*Tabla2[[#This Row],[Cantidad]] -> 7922.2 | N40: =Tabla2[[#This Row],[Subtotal ARS]]+(Tabla2[[#This Row],[Subtotal ARS]]*Tabla2[[#This Row],[IVA]]) -> 9585.862 | O40: =Tabla2[[#This Row],[TOTAL ARS]]/Tabla2[[#This Row],[TC BNA]] -> 6.7034 | P40: =_xlfn.XLOOKUP(A40,'TC_BNA xlsx'!A:A,'TC_BNA xlsx'!C:C,"No encontrado") -> 1430
...

Sheet Cotizaciones
A1: Fecha | B1: Artículo | C1: Cantidad | D1: Unidad | E1: Precio Cotizado | F1: Últ. Precio | G1: Último Proveedor | H1: Mejor Precio | I1: Mejor Proveedor | J1: Variación vs Últ. Precio | K1: Dif por Unidad | L1: Sobrecosto Total | M1: Estado | N1: Observaciones
A2: 46222 | B2: Zapato Ombú prusiano | C2: 2 | D2: unidad | E2: 59000 | F2: =IF(Tabla4[[#This Row],[Artículo]]="","",IFERROR(_xlfn.XLOOKUP(Tabla4[[#This Row],[Artículo]],Tabla2[Artículo],Tabla2[Precio Unitario ARS],"",0,-1),"")) -> 59000 | G2: =IF(Tabla4[[#This Row],[Artículo]]="","",IFERROR(_xlfn.XLOOKUP(Tabla4[[#This Row],[Artículo]],Tabla2[Artículo],Tabla2[Proveedor],"",0,-1),"")) -> Aníbal Roncoroni | H2: {=IF(Tabla4[[#This Row],[Artículo]]="","",IFERROR(MIN(_xlfn._xlws.FILTER(Tabla2[Precio Unitario ARS],Tabla2[Artículo]=Tabla4[[#This Row],[Artículo]])),""))} -> 49509.2 | I2: {=IF(Tabla4[[#This Row],[Artículo]]="","",IFERROR(_xlfn.XLOOKUP(1,(Tabla2[Artículo]=Tabla4[[#This Row],[Artículo]])*(Tabla2[Precio Unitario ARS]=Tabla4[[#This Row],[Mejor Precio]]),Tabla2[Proveedor]),""))} -> Tech Safe | J2: =IF(Tabla4[[#This Row],[Artículo]]="","",IFERROR((Tabla4[[#This Row],[Precio Cotizado]]-Tabla4[[#This Row],[Últ. Precio]])/Tabla4[[#This Row],[Últ. Precio]],"")) -> 0 | K2: =IF(Tabla4[[#This Row],[Artículo]]="","",IFERROR(Tabla4[[#This Row],[Precio Cotizado]]-Tabla4[[#This Row],[Mejor Precio]],"")) -> 9490.8 | L2: =IF(Tabla4[[#This Row],[Artículo]]="","",IFERROR(Tabla4[[#This Row],[Dif por Unidad]]*Tabla4[[#This Row],[Cantidad]],"")) -> 18981.6 | M2: =IF(B2="","",IF(J2<0,"Más barato",IF(J2<=5%,"Dentro del rango",IF(J2<=15%,"Revisar","Precio alto")))) -> Dentro del rango | N2: =IF(Tabla4[[#This Row],[Artículo]]="","",IF(Tabla4[[#This Row],[Estado]]="Más barato","✓ Conviene comprar. Ahorro respecto al mejor precio.",IF(Tabla4[[#This Row],[Estado]]="Dentro del rango","✓ Precio dentro del rango habitual.",IF(Tabla4[[#This Row],[Estado]]="Revisar","⚠ Solicitar otra cotización.","🚨 Precio elevado. Negociar o buscar alternativa.")))) -> ✓ Precio dentro del rango habitual.
A3: 46227 | B3: Varilla Roscada Zinc. 1/4" | C3: 2000 | D3: unidad | E3: 472.5 | F3: =IF(Tabla4[[#This Row],[Artículo]]="","",IFERROR(_xlfn.XLOOKUP(Tabla4[[#This Row],[Artículo]],Tabla2[Artículo],Tabla2[Precio Unitario ARS],"",0,-1),"")) -> 463.05 | G3: =IF(Tabla4[[#This Row],[Artículo]]="","",IFERROR(_xlfn.XLOOKUP(Tabla4[[#This Row],[Artículo]],Tabla2[Artículo],Tabla2[Proveedor],"",0,-1),"")) -> Dusvar | H3: {=IF(Tabla4[[#This Row],[Artículo]]="","",IFERROR(MIN(_xlfn._xlws.FILTER(Tabla2[Precio Unitario ARS],Tabla2[Artículo]=Tabla4[[#This Row],[Artículo]])),""))} -> 450 | I3: {=IF(Tabla4[[#This Row],[Artículo]]="","",IFERROR(_xlfn.XLOOKUP(1,(Tabla2[Artículo]=Tabla4[[#This Row],[Artículo]])*(Tabla2[Precio Unitario ARS]=Tabla4[[#This Row],[Mejor Precio]]),Tabla2[Proveedor]),""))} -> Dusvar | J3: =IF(Tabla4[[#This Row],[Artículo]]="","",IFERROR((Tabla4[[#This Row],[Precio Cotizado]]-Tabla4[[#This Row],[Últ. Precio]])/Tabla4[[#This Row],[Últ. Precio]],"")) -> 0.020408163 | K3: =IF(Tabla4[[#This Row],[Artículo]]="","",IFERROR(Tabla4[[#This Row],[Precio Cotizado]]-Tabla4[[#This Row],[Mejor Precio]],"")) -> 22.5 | L3: =IF(Tabla4[[#This Row],[Artículo]]="","",IFERROR(Tabla4[[#This Row],[Dif por Unidad]]*Tabla4[[#This Row],[Cantidad]],"")) -> 45000 | M3: =IF(B3="","",IF(J3<0,"Más barato",IF(J3<=5%,"Dentro del rango",IF(J3<=15%,"Revisar","Precio alto")))) -> Dentro del rango | N3: =IF(Tabla4[[#This Row],[Artículo]]="","",IF(Tabla4[[#This Row],[Estado]]="Más barato","✓ Conviene comprar. Ahorro respecto al mejor precio.",IF(Tabla4[[#This Row],[Estado]]="Dentro del rango","✓ Precio dentro del rango habitual.",IF(Tabla4[[#This Row],[Estado]]="Revisar","⚠ Solicitar otra cotización.","🚨 Precio elevado. Negociar o buscar alternativa.")))) -> ✓ Precio dentro del rango habitual.
A4: 46227 | B4: Varilla Roscada Zinc. 3/8" | C4: 700 | D4: unidad | E4: 1026.95 | F4: =IF(Tabla4[[#This Row],[Artículo]]="","",IFERROR(_xlfn.XLOOKUP(Tabla4[[#This Row],[Artículo]],Tabla2[Artículo],Tabla2[Precio Unitario ARS],"",0,-1),"")) -> 1026 | G4: =IF(Tabla4[[#This Row],[Artículo]]="","",IFERROR(_xlfn.XLOOKUP(Tabla4[[#This Row],[Artículo]],Tabla2[Artículo],Tabla2[Proveedor],"",0,-1),"")) -> Dusvar | H4: {=IF(Tabla4[[#This Row],[Artículo]]="","",IFERROR(MIN(_xlfn._xlws.FILTER(Tabla2[Precio Unitario ARS],Tabla2[Artículo]=Tabla4[[#This Row],[Artículo]])),""))} -> 998 | I4: {=IF(Tabla4[[#This Row],[Artículo]]="","",IFERROR(_xlfn.XLOOKUP(1,(Tabla2[Artículo]=Tabla4[[#This Row],[Artículo]])*(Tabla2[Precio Unitario ARS]=Tabla4[[#This Row],[Mejor Precio]]),Tabla2[Proveedor]),""))} -> Dusvar | J4: =IF(Tabla4[[#This Row],[Artículo]]="","",IFERROR((Tabla4[[#This Row],[Precio Cotizado]]-Tabla4[[#This Row],[Últ. Precio]])/Tabla4[[#This Row],[Últ. Precio]],"")) -> 0.00092592593 | K4: =IF(Tabla4[[#This Row],[Artículo]]="","",IFERROR(Tabla4[[#This Row],[Precio Cotizado]]-Tabla4[[#This Row],[Mejor Precio]],"")) -> 28.95 | L4: =IF(Tabla4[[#This Row],[Artículo]]="","",IFERROR(Tabla4[[#This Row],[Dif por Unidad]]*Tabla4[[#This Row],[Cantidad]],"")) -> 20265 | M4: =IF(B4="","",IF(J4<0,"Más barato",IF(J4<=5%,"Dentro del rango",IF(J4<=15%,"Revisar","Precio alto")))) -> Dentro del rango | N4: =IF(Tabla4[[#This Row],[Artículo]]="","",IF(Tabla4[[#This Row],[Estado]]="Más barato","✓ Conviene comprar. Ahorro respecto al mejor precio.",IF(Tabla4[[#This Row],[Estado]]="Dentro del rango","✓ Precio dentro del rango habitual.",IF(Tabla4[[#This Row],[Estado]]="Revisar","⚠ Solicitar otra cotización.","🚨 Precio elevado. Negociar o buscar alternativa.")))) -> ✓ Precio dentro del rango habitual.
A5: 46227 | B5: Varilla Roscada Zinc. 5/16" | C5: 1000 | D5: unidad | E5: 730.26 | F5: =IF(Tabla4[[#This Row],[Artículo]]="","",IFERROR(_xlfn.XLOOKUP(Tabla4[[#This Row],[Artículo]],Tabla2[Artículo],Tabla2[Precio Unitario ARS],"",0,-1),"")) -> 730.26 | G5: =IF(Tabla4[[#This Row],[Artículo]]="","",IFERROR(_xlfn.XLOOKUP(Tabla4[[#This Row],[Artículo]],Tabla2[Artículo],Tabla2[Proveedor],"",0,-1),"")) -> Dusvar | H5: {=IF(Tabla4[[#This Row],[Artículo]]="","",IFERROR(MIN(_xlfn._xlws.FILTER(Tabla2[Precio Unitario ARS],Tabla2[Artículo]=Tabla4[[#This Row],[Artículo]])),""))} -> 717 | I5: {=IF(Tabla4[[#This Row],[Artículo]]="","",IFERROR(_xlfn.XLOOKUP(1,(Tabla2[Artículo]=Tabla4[[#This Row],[Artículo]])*(Tabla2[Precio Unitario ARS]=Tabla4[[#This Row],[Mejor Precio]]),Tabla2[Proveedor]),""))} -> Dusvar | J5: =IF(Tabla4[[#This Row],[Artículo]]="","",IFERROR((Tabla4[[#This Row],[Precio Cotizado]]-Tabla4[[#This Row],[Últ. Precio]])/Tabla4[[#This Row],[Últ. Precio]],"")) -> 0 | K5: =IF(Tabla4[[#This Row],[Artículo]]="","",IFERROR(Tabla4[[#This Row],[Precio Cotizado]]-Tabla4[[#This Row],[Mejor Precio]],"")) -> 13.26 | L5: =IF(Tabla4[[#This Row],[Artículo]]="","",IFERROR(Tabla4[[#This Row],[Dif por Unidad]]*Tabla4[[#This Row],[Cantidad]],"")) -> 13260 | M5: =IF(B5="","",IF(J5<0,"Más barato",IF(J5<=5%,"Dentro del rango",IF(J5<=15%,"Revisar","Precio alto")))) -> Dentro del rango | N5: =IF(Tabla4[[#This Row],[Artículo]]="","",IF(Tabla4[[#This Row],[Estado]]="Más barato","✓ Conviene comprar. Ahorro respecto al mejor precio.",IF(Tabla4[[#This Row],[Estado]]="Dentro del rango","✓ Precio dentro del rango habitual.",IF(Tabla4[[#This Row],[Estado]]="Revisar","⚠ Solicitar otra cotización.","🚨 Precio elevado. Negociar o buscar alternativa.")))) -> ✓ Precio dentro del rango habitual.
A6: 46227 | B6: Lysoform | C6: 5 | E6: 3462.8 | F6: =IF(Tabla4[[#This Row],[Artículo]]="","",IFERROR(_xlfn.XLOOKUP(Tabla4[[#This Row],[Artículo]],Tabla2[Artículo],Tabla2[Precio Unitario ARS],"",0,-1),"")) -> 3462.8 | G6: =IF(Tabla4[[#This Row],[Artículo]]="","",IFERROR(_xlfn.XLOOKUP(Tabla4[[#This Row],[Artículo]],Tabla2[Artículo],Tabla2[Proveedor],"",0,-1),"")) -> Imperio de la Limpieza | H6: {=IF(Tabla4[[#This Row],[Artículo]]="","",IFERROR(MIN(_xlfn._xlws.FILTER(Tabla2[Precio Unitario ARS],Tabla2[Artículo]=Tabla4[[#This Row],[Artículo]])),""))} -> 3198.34 | I6: {=IF(Tabla4[[#This Row],[Artículo]]="","",IFERROR(_xlfn.XLOOKUP(1,(Tabla2[Artículo]=Tabla4[[#This Row],[Artículo]])*(Tabla2[Precio Unitario ARS]=Tabla4[[#This Row],[Mejor Precio]]),Tabla2[Proveedor]),""))} -> Imperio de la Limpieza | J6: =IF(Tabla4[[#This Row],[Artículo]]="","",IFERROR((Tabla4[[#This Row],[Precio Cotizado]]-Tabla4[[#This Row],[Últ. Precio]])/Tabla4[[#This Row],[Últ. Precio]],"")) -> 0 | K6: =IF(Tabla4[[#This Row],[Artículo]]="","",IFERROR(Tabla4[[#This Row],[Precio Cotizado]]-Tabla4[[#This Row],[Mejor Precio]],"")) -> 264.46 | L6: =IF(Tabla4[[#This Row],[Artículo]]="","",IFERROR(Tabla4[[#This Row],[Dif por Unidad]]*Tabla4[[#This Row],[Cantidad]],"")) -> 1322.3 | M6: =IF(B6="","",IF(J6<0,"Más barato",IF(J6<=5%,"Dentro del rango",IF(J6<=15%,"Revisar","Precio alto")))) -> Dentro del rango | N6: =IF(Tabla4[[#This Row],[Artículo]]="","",IF(Tabla4[[#This Row],[Estado]]="Más barato","✓ Conviene comprar. Ahorro respecto al mejor precio.",IF(Tabla4[[#This Row],[Estado]]="Dentro del rango","✓ Precio dentro del rango habitual.",IF(Tabla4[[#This Row],[Estado]]="Revisar","⚠ Solicitar otra cotización.","🚨 Precio elevado. Negociar o buscar alternativa.")))) -> ✓ Precio dentro del rango habitual.
A7: 46227 | B7: Bolsas 50x70 | C7: 15 | E7: =611.57/15 -> 40.771333 | F7: =IF(Tabla4[[#This Row],[Artículo]]="","",IFERROR(_xlfn.XLOOKUP(Tabla4[[#This Row],[Artículo]],Tabla2[Artículo],Tabla2[Precio Unitario ARS],"",0,-1),"")) -> 611.57 | G7: =IF(Tabla4[[#This Row],[Artículo]]="","",IFERROR(_xlfn.XLOOKUP(Tabla4[[#This Row],[Artículo]],Tabla2[Artículo],Tabla2[Proveedor],"",0,-1),"")) -> Imperio de la Limpieza | H7: {=IF(Tabla4[[#This Row],[Artículo]]="","",IFERROR(MIN(_xlfn._xlws.FILTER(Tabla2[Precio Unitario ARS],Tabla2[Artículo]=Tabla4[[#This Row],[Artículo]])),""))} -> 61.157 | I7: {=IF(Tabla4[[#This Row],[Artículo]]="","",IFERROR(_xlfn.XLOOKUP(1,(Tabla2[Artículo]=Tabla4[[#This Row],[Artículo]])*(Tabla2[Precio Unitario ARS]=Tabla4[[#This Row],[Mejor Precio]]),Tabla2[Proveedor]),""))} -> Imperio de la Limpieza | J7: =IF(Tabla4[[#This Row],[Artículo]]="","",IFERROR((Tabla4[[#This Row],[Precio Cotizado]]-Tabla4[[#This Row],[Últ. Precio]])/Tabla4[[#This Row],[Últ. Precio]],"")) -> -0.93333333 | K7: =IF(Tabla4[[#This Row],[Artículo]]="","",IFERROR(Tabla4[[#This Row],[Precio Cotizado]]-Tabla4[[#This Row],[Mejor Precio]],"")) -> -20.385667 | L7: =IF(Tabla4[[#This Row],[Artículo]]="","",IFERROR(Tabla4[[#This Row],[Dif por Unidad]]*Tabla4[[#This Row],[Cantidad]],"")) -> -305.785 | M7: =IF(B7="","",IF(J7<0,"Más barato",IF(J7<=5%,"Dentro del rango",IF(J7<=15%,"Revisar","Precio alto")))) -> Más barato | N7: =IF(Tabla4[[#This Row],[Artículo]]="","",IF(Tabla4[[#This Row],[Estado]]="Más barato","✓ Conviene comprar. Ahorro respecto al mejor precio.",IF(Tabla4[[#This Row],[Estado]]="Dentro del rango","✓ Precio dentro del rango habitual.",IF(Tabla4[[#This Row],[Estado]]="Revisar","⚠ Solicitar otra cotización.","🚨 Precio elevado. Negociar o buscar alternativa.")))) -> ✓ Conviene comprar. Ahorro respecto al mejor precio.
A8: 46227 | B8: Bolsas 80x110 | C8: 10 | E8: =1876.03/10 -> 187.603 | F8: =IF(Tabla4[[#This Row],[Artículo]]="","",IFERROR(_xlfn.XLOOKUP(Tabla4[[#This Row],[Artículo]],Tabla2[Artículo],Tabla2[Precio Unitario ARS],"",0,-1),"")) -> 1876.03 | G8: =IF(Tabla4[[#This Row],[Artículo]]="","",IFERROR(_xlfn.XLOOKUP(Tabla4[[#This Row],[Artículo]],Tabla2[Artículo],Tabla2[Proveedor],"",0,-1),"")) -> Imperio de la Limpieza | H8: {=IF(Tabla4[[#This Row],[Artículo]]="","",IFERROR(MIN(_xlfn._xlws.FILTER(Tabla2[Precio Unitario ARS],Tabla2[Artículo]=Tabla4[[#This Row],[Artículo]])),""))} -> 187.603 | I8: {=IF(Tabla4[[#This Row],[Artículo]]="","",IFERROR(_xlfn.XLOOKUP(1,(Tabla2[Artículo]=Tabla4[[#This Row],[Artículo]])*(Tabla2[Precio Unitario ARS]=Tabla4[[#This Row],[Mejor Precio]]),Tabla2[Proveedor]),""))} -> Imperio de la Limpieza | J8: =IF(Tabla4[[#This Row],[Artículo]]="","",IFERROR((Tabla4[[#This Row],[Precio Cotizado]]-Tabla4[[#This Row],[Últ. Precio]])/Tabla4[[#This Row],[Últ. Precio]],"")) -> -0.9 | K8: =IF(Tabla4[[#This Row],[Artículo]]="","",IFERROR(Tabla4[[#This Row],[Precio Cotizado]]-Tabla4[[#This Row],[Mejor Precio]],"")) -> 0 | L8: =IF(Tabla4[[#This Row],[Artículo]]="","",IFERROR(Tabla4[[#This Row],[Dif por Unidad]]*Tabla4[[#This Row],[Cantidad]],"")) -> 0 | M8: =IF(B8="","",IF(J8<0,"Más barato",IF(J8<=5%,"Dentro del rango",IF(J8<=15%,"Revisar","Precio alto")))) -> Más barato | N8: =IF(Tabla4[[#This Row],[Artículo]]="","",IF(Tabla4[[#This Row],[Estado]]="Más barato","✓ Conviene comprar. Ahorro respecto al mejor precio.",IF(Tabla4[[#This Row],[Estado]]="Dentro del rango","✓ Precio dentro del rango habitual.",IF(Tabla4[[#This Row],[Estado]]="Revisar","⚠ Solicitar otra cotización.","🚨 Precio elevado. Negociar o buscar alternativa.")))) -> ✓ Conviene comprar. Ahorro respecto al mejor precio.
A9: 46227 | B9: Esponjas | C9: 5 | E9: 553.71 | F9: =IF(Tabla4[[#This Row],[Artículo]]="","",IFERROR(_xlfn.XLOOKUP(Tabla4[[#This Row],[Artículo]],Tabla2[Artículo],Tabla2[Precio Unitario ARS],"",0,-1),"")) -> 553.71 | G9: =IF(Tabla4[[#This Row],[Artículo]]="","",IFERROR(_xlfn.XLOOKUP(Tabla4[[#This Row],[Artículo]],Tabla2[Artículo],Tabla2[Proveedor],"",0,-1),"")) -> Imperio de la Limpieza | H9: {=IF(Tabla4[[#This Row],[Artículo]]="","",IFERROR(MIN(_xlfn._xlws.FILTER(Tabla2[Precio Unitario ARS],Tabla2[Artículo]=Tabla4[[#This Row],[Artículo]])),""))} -> 504.13 | I9: {=IF(Tabla4[[#This Row],[Artículo]]="","",IFERROR(_xlfn.XLOOKUP(1,(Tabla2[Artículo]=Tabla4[[#This Row],[Artículo]])*(Tabla2[Precio Unitario ARS]=Tabla4[[#This Row],[Mejor Precio]]),Tabla2[Proveedor]),""))} -> Imperio de la Limpieza | J9: =IF(Tabla4[[#This Row],[Artículo]]="","",IFERROR((Tabla4[[#This Row],[Precio Cotizado]]-Tabla4[[#This Row],[Últ. Precio]])/Tabla4[[#This Row],[Últ. Precio]],"")) -> 0 | K9: =IF(Tabla4[[#This Row],[Artículo]]="","",IFERROR(Tabla4[[#This Row],[Precio Cotizado]]-Tabla4[[#This Row],[Mejor Precio]],"")) -> 49.58 | L9: =IF(Tabla4[[#This Row],[Artículo]]="","",IFERROR(Tabla4[[#This Row],[Dif por Unidad]]*Tabla4[[#This Row],[Cantidad]],"")) -> 247.9 | M9: =IF(B9="","",IF(J9<0,"Más barato",IF(J9<=5%,"Dentro del rango",IF(J9<=15%,"Revisar","Precio alto")))) -> Dentro del rango | N9: =IF(Tabla4[[#This Row],[Artículo]]="","",IF(Tabla4[[#This Row],[Estado]]="Más barato","✓ Conviene comprar. Ahorro respecto al mejor precio.",IF(Tabla4[[#This Row],[Estado]]="Dentro del rango","✓ Precio dentro del rango habitual.",IF(Tabla4[[#This Row],[Estado]]="Revisar","⚠ Solicitar otra cotización.","🚨 Precio elevado. Negociar o buscar alternativa.")))) -> ✓ Precio dentro del rango habitual.
A10: 46227 | B10: Desodorante p/piso Lavanda | C10: 5 | E10: 2933.88 | F10: =IF(Tabla4[[#This Row],[Artículo]]="","",IFERROR(_xlfn.XLOOKUP(Tabla4[[#This Row],[Artículo]],Tabla2[Artículo],Tabla2[Precio Unitario ARS],"",0,-1),"")) -> 2933.88 | G10: =IF(Tabla4[[#This Row],[Artículo]]="","",IFERROR(_xlfn.XLOOKUP(Tabla4[[#This Row],[Artículo]],Tabla2[Artículo],Tabla2[Proveedor],"",0,-1),"")) -> Imperio de la Limpieza | H10: {=IF(Tabla4[[#This Row],[Artículo]]="","",IFERROR(MIN(_xlfn._xlws.FILTER(Tabla2[Precio Unitario ARS],Tabla2[Artículo]=Tabla4[[#This Row],[Artículo]])),""))} -> 561.982 | I10: {=IF(Tabla4[[#This Row],[Artículo]]="","",IFERROR(_xlfn.XLOOKUP(1,(Tabla2[Artículo]=Tabla4[[#This Row],[Artículo]])*(Tabla2[Precio Unitario ARS]=Tabla4[[#This Row],[Mejor Precio]]),Tabla2[Proveedor]),""))} -> Imperio de la Limpieza | J10: =IF(Tabla4[[#This Row],[Artículo]]="","",IFERROR((Tabla4[[#This Row],[Precio Cotizado]]-Tabla4[[#This Row],[Últ. Precio]])/Tabla4[[#This Row],[Últ. Precio]],"")) -> 0 | K10: =IF(Tabla4[[#This Row],[Artículo]]="","",IFERROR(Tabla4[[#This Row],[Precio Cotizado]]-Tabla4[[#This Row],[Mejor Precio]],"")) -> 2371.898 | L10: =IF(Tabla4[[#This Row],[Artículo]]="","",IFERROR(Tabla4[[#This Row],[Dif por Unidad]]*Tabla4[[#This Row],[Cantidad]],"")) -> 11859.49 | M10: =IF(B10="","",IF(J10<0,"Más barato",IF(J10<=5%,"Dentro del rango",IF(J10<=15%,"Revisar","Precio alto")))) -> Dentro del rango | N10: =IF(Tabla4[[#This Row],[Artículo]]="","",IF(Tabla4[[#This Row],[Estado]]="Más barato","✓ Conviene comprar. Ahorro respecto al mejor precio.",IF(Tabla4[[#This Row],[Estado]]="Dentro del rango","✓ Precio dentro del rango habitual.",IF(Tabla4[[#This Row],[Estado]]="Revisar","⚠ Solicitar otra cotización.","🚨 Precio elevado. Negociar o buscar alternativa.")))) -> ✓ Precio dentro del rango habitual.
A11: 46227 | B11: Guantes de limpieza (Talle L) | C11: 1 | E11: 2917.35 | F11: =IF(Tabla4[[#This Row],[Artículo]]="","",IFERROR(_xlfn.XLOOKUP(Tabla4[[#This Row],[Artículo]],Tabla2[Artículo],Tabla2[Precio Unitario ARS],"",0,-1),"")) -> 2917.35 | G11: =IF(Tabla4[[#This Row],[Artículo]]="","",IFERROR(_xlfn.XLOOKUP(Tabla4[[#This Row],[Artículo]],Tabla2[Artículo],Tabla2[Proveedor],"",0,-1),"")) -> Imperio de la Limpieza | H11: {=IF(Tabla4[[#This Row],[Artículo]]="","",IFERROR(MIN(_xlfn._xlws.FILTER(Tabla2[Precio Unitario ARS],Tabla2[Artículo]=Tabla4[[#This Row],[Artículo]])),""))} -> 2628.09 | I11: {=IF(Tabla4[[#This Row],[Artículo]]="","",IFERROR(_xlfn.XLOOKUP(1,(Tabla2[Artículo]=Tabla4[[#This Row],[Artículo]])*(Tabla2[Precio Unitario ARS]=Tabla4[[#This Row],[Mejor Precio]]),Tabla2[Proveedor]),""))} -> Imperio de la Limpieza | J11: =IF(Tabla4[[#This Row],[Artículo]]="","",IFERROR((Tabla4[[#This Row],[Precio Cotizado]]-Tabla4[[#This Row],[Últ. Precio]])/Tabla4[[#This Row],[Últ. Precio]],"")) -> 0 | K11: =IF(Tabla4[[#This Row],[Artículo]]="","",IFERROR(Tabla4[[#This Row],[Precio Cotizado]]-Tabla4[[#This Row],[Mejor Precio]],"")) -> 289.26 | L11: =IF(Tabla4[[#This Row],[Artículo]]="","",IFERROR(Tabla4[[#This Row],[Dif por Unidad]]*Tabla4[[#This Row],[Cantidad]],"")) -> 289.26 | M11: =IF(B11="","",IF(J11<0,"Más barato",IF(J11<=5%,"Dentro del rango",IF(J11<=15%,"Revisar","Precio alto")))) -> Dentro del rango | N11: =IF(Tabla4[[#This Row],[Artículo]]="","",IF(Tabla4[[#This Row],[Estado]]="Más barato","✓ Conviene comprar. Ahorro respecto al mejor precio.",IF(Tabla4[[#This Row],[Estado]]="Dentro del rango","✓ Precio dentro del rango habitual.",IF(Tabla4[[#This Row],[Estado]]="Revisar","⚠ Solicitar otra cotización.","🚨 Precio elevado. Negociar o buscar alternativa.")))) -> ✓ Precio dentro del rango habitual.
A12: 46227 | B12: Jabón líquido | C12: 1 | E12: 9008.23 | F12: =IF(Tabla4[[#This Row],[Artículo]]="","",IFERROR(_xlfn.XLOOKUP(Tabla4[[#This Row],[Artículo]],Tabla2[Artículo],Tabla2[Precio Unitario ARS],"",0,-1),"")) -> 9008.26 | G12: =IF(Tabla4[[#This Row],[Artículo]]="","",IFERROR(_xlfn.XLOOKUP(Tabla4[[#This Row],[Artículo]],Tabla2[Artículo],Tabla2[Proveedor],"",0,-1),"")) -> Imperio de la Limpieza | H12: {=IF(Tabla4[[#This Row],[Artículo]]="","",IFERROR(MIN(_xlfn._xlws.FILTER(Tabla2[Precio Unitario ARS],Tabla2[Artículo]=Tabla4[[#This Row],[Artículo]])),""))} -> 1692.56 | I12: {=IF(Tabla4[[#This Row],[Artículo]]="","",IFERROR(_xlfn.XLOOKUP(1,(Tabla2[Artículo]=Tabla4[[#This Row],[Artículo]])*(Tabla2[Precio Unitario ARS]=Tabla4[[#This Row],[Mejor Precio]]),Tabla2[Proveedor]),""))} -> Imperio de la Limpieza | J12: =IF(Tabla4[[#This Row],[Artículo]]="","",IFERROR((Tabla4[[#This Row],[Precio Cotizado]]-Tabla4[[#This Row],[Últ. Precio]])/Tabla4[[#This Row],[Últ. Precio]],"")) -> -3.3302769e-06 | K12: =IF(Tabla4[[#This Row],[Artículo]]="","",IFERROR(Tabla4[[#This Row],[Precio Cotizado]]-Tabla4[[#This Row],[Mejor Precio]],"")) -> 7315.67 | L12: =IF(Tabla4[[#This Row],[Artículo]]="","",IFERROR(Tabla4[[#This Row],[Dif por Unidad]]*Tabla4[[#This Row],[Cantidad]],"")) -> 7315.67 | M12: =IF(B12="","",IF(J12<0,"Más barato",IF(J12<=5%,"Dentro del rango",IF(J12<=15%,"Revisar","Precio alto")))) -> Más barato | N12: =IF(Tabla4[[#This Row],[Artículo]]="","",IF(Tabla4[[#This Row],[Estado]]="Más barato","✓ Conviene comprar. Ahorro respecto al mejor precio.",IF(Tabla4[[#This Row],[Estado]]="Dentro del rango","✓ Precio dentro del rango habitual.",IF(Tabla4[[#This Row],[Estado]]="Revisar","⚠ Solicitar otra cotización.","🚨 Precio elevado. Negociar o buscar alternativa.")))) -> ✓ Conviene comprar. Ahorro respecto al mejor precio.
A13: 46227 | B13: Detergente | C13: 3 | F13: =IF(Tabla4[[#This Row],[Artículo]]="","",IFERROR(_xlfn.XLOOKUP(Tabla4[[#This Row],[Artículo]],Tabla2[Artículo],Tabla2[Precio Unitario ARS],"",0,-1),"")) -> 9000 | G13: =IF(Tabla4[[#This Row],[Artículo]]="","",IFERROR(_xlfn.XLOOKUP(Tabla4[[#This Row],[Artículo]],Tabla2[Artículo],Tabla2[Proveedor],"",0,-1),"")) -> Imperio de la Limpieza | H13: {=IF(Tabla4[[#This Row],[Artículo]]="","",IFERROR(MIN(_xlfn._xlws.FILTER(Tabla2[Precio Unitario ARS],Tabla2[Artículo]=Tabla4[[#This Row],[Artículo]])),""))} -> 1647.932 | I13: {=IF(Tabla4[[#This Row],[Artículo]]="","",IFERROR(_xlfn.XLOOKUP(1,(Tabla2[Artículo]=Tabla4[[#This Row],[Artículo]])*(Tabla2[Precio Unitario ARS]=Tabla4[[#This Row],[Mejor Precio]]),Tabla2[Proveedor]),""))} -> Imperio de la Limpieza | J13: =IF(Tabla4[[#This Row],[Artículo]]="","",IFERROR((Tabla4[[#This Row],[Precio Cotizado]]-Tabla4[[#This Row],[Últ. Precio]])/Tabla4[[#This Row],[Últ. Precio]],"")) -> -1 | K13: =IF(Tabla4[[#This Row],[Artículo]]="","",IFERROR(Tabla4[[#This Row],[Precio Cotizado]]-Tabla4[[#This Row],[Mejor Precio]],"")) -> -1647.932 | L13: =IF(Tabla4[[#This Row],[Artículo]]="","",IFERROR(Tabla4[[#This Row],[Dif por Unidad]]*Tabla4[[#This Row],[Cantidad]],"")) -> -4943.796 | M13: =IF(B13="","",IF(J13<0,"Más barato",IF(J13<=5%,"Dentro del rango",IF(J13<=15%,"Revisar","Precio alto")))) -> Más barato | N13: =IF(Tabla4[[#This Row],[Artículo]]="","",IF(Tabla4[[#This Row],[Estado]]="Más barato","✓ Conviene comprar. Ahorro respecto al mejor precio.",IF(Tabla4[[#This Row],[Estado]]="Dentro del rango","✓ Precio dentro del rango habitual.",IF(Tabla4[[#This Row],[Estado]]="Revisar","⚠ Solicitar otra cotización.","🚨 Precio elevado. Negociar o buscar alternativa.")))) -> ✓ Conviene comprar. Ahorro respecto al mejor precio.
A14: 46227 | B14: Lavandina Líquida | C14: 2 | F14: =IF(Tabla4[[#This Row],[Artículo]]="","",IFERROR(_xlfn.XLOOKUP(Tabla4[[#This Row],[Artículo]],Tabla2[Artículo],Tabla2[Precio Unitario ARS],"",0,-1),"")) -> 3801.65 | G14: =IF(Tabla4[[#This Row],[Artículo]]="","",IFERROR(_xlfn.XLOOKUP(Tabla4[[#This Row],[Artículo]],Tabla2[Artículo],Tabla2[Proveedor],"",0,-1),"")) -> Imperio de la Limpieza | H14: {=IF(Tabla4[[#This Row],[Artículo]]="","",IFERROR(MIN(_xlfn._xlws.FILTER(Tabla2[Precio Unitario ARS],Tabla2[Artículo]=Tabla4[[#This Row],[Artículo]])),""))} -> 3801.65 | I14: {=IF(Tabla4[[#This Row],[Artículo]]="","",IFERROR(_xlfn.XLOOKUP(1,(Tabla2[Artículo]=Tabla4[[#This Row],[Artículo]])*(Tabla2[Precio Unitario ARS]=Tabla4[[#This Row],[Mejor Precio]]),Tabla2[Proveedor]),""))} -> Imperio de la Limpieza | J14: =IF(Tabla4[[#This Row],[Artículo]]="","",IFERROR((Tabla4[[#This Row],[Precio Cotizado]]-Tabla4[[#This Row],[Últ. Precio]])/Tabla4[[#This Row],[Últ. Precio]],"")) -> -1 | K14: =IF(Tabla4[[#This Row],[Artículo]]="","",IFERROR(Tabla4[[#This Row],[Precio Cotizado]]-Tabla4[[#This Row],[Mejor Precio]],"")) -> -3801.65 | L14: =IF(Tabla4[[#This Row],[Artículo]]="","",IFERROR(Tabla4[[#This Row],[Dif por Unidad]]*Tabla4[[#This Row],[Cantidad]],"")) -> -7603.3 | M14: =IF(B14="","",IF(J14<0,"Más barato",IF(J14<=5%,"Dentro del rango",IF(J14<=15%,"Revisar","Precio alto")))) -> Más barato | N14: =IF(Tabla4[[#This Row],[Artículo]]="","",IF(Tabla4[[#This Row],[Estado]]="Más barato","✓ Conviene comprar. Ahorro respecto al mejor precio.",IF(Tabla4[[#This Row],[Estado]]="Dentro del rango","✓ Precio dentro del rango habitual.",IF(Tabla4[[#This Row],[Estado]]="Revisar","⚠ Solicitar otra cotización.","🚨 Precio elevado. Negociar o buscar alternativa.")))) -> ✓ Conviene comprar. Ahorro respecto al mejor precio.
